<?xml version="1.0" ?>
<sdf version="1.5">
  <model name="turtlebot3_burger">  

    <link name="base">

      <inertial>
        <pose>-0.032 0 0.070 0 0 0</pose>
        <inertia>
          <ixx>0.001</ixx>
          <ixy>0.000</ixy>
          <ixz>0.000</ixz>
          <iyy>0.001</iyy>
          <iyz>0.000</iyz>
          <izz>0.001</izz>
        </inertia>
        <mass>1.0</mass>
      </inertial>

      <collision name="base_collision">
        <pose>-0.032 0 0.070 0 0 0</pose>
        <geometry>
          <box>
            <size>0.140 0.140 0.140</size>
          </box>
        </geometry>
      </collision>

      <visual name="base_visual">
        <pose>-0.032 0 0 0 0 0</pose>
        <geometry>
          <mesh>
            <uri>model://turtleBot/meshes/burger_base.stl</uri>
            <scale>0.001 0.001 0.001</scale>
          </mesh>
        </geometry>
      </visual>

      <collision name="caster_collision">
        <pose>-0.081 0 -0.004 0 0 0</pose>
        <geometry>
          <sphere>
            <radius>0.005000</radius>
          </sphere>
        </geometry>
        <surface>
          <friction>
            <ode>
              <mu>100000.0</mu>
              <mu2>100000.0</mu2>
              <fdir1>0 0 0</fdir1>
              <slip1>0</slip1>
              <slip2>0</slip2>
            </ode>
          </friction>
        </surface>
      </collision>
    </link>

  <link name="lidar">
    <inertial>
      <pose>-0.020 0 0.161 0 0 0</pose>
      <inertia>
        <ixx>0.001</ixx>
        <ixy>0.000</ixy>
        <ixz>0.000</ixz>
        <iyy>0.001</iyy>
        <iyz>0.000</iyz>
        <izz>0.001</izz>
      </inertia>
      <mass>0.125</mass>
    </inertial>

    <collision name="lidar_sensor_collision">
        <pose>-0.020 0 0.161 0 0 0</pose>
        <geometry>
          <cylinder>
            <radius>0.0508</radius>
            <length>0.055</length>
          </cylinder>
        </geometry>
      </collision>

      <visual name="lidar_sensor_visual">
        <pose>-0.032 0 0.171 0 0 0</pose>
        <geometry>
          <mesh>
            <uri>model://turtleBot/meshes/lds.stl</uri>
            <scale>0.001 0.001 0.001</scale>
          </mesh>
        </geometry>
      </visual>

      <sensor name="hls_lfcd_lds" type="ray">
        <always_on>1</always_on>
        <visualize>0</visualize>
        <pose>-0.032 0 0.171 0 0 0</pose>
        <update_rate>1800</update_rate>
        <ray>
          <scan>
            <horizontal>
              <samples>360</samples>
              <resolution>1.000000</resolution>
              <min_angle>0.000000</min_angle>
              <max_angle>6.280000</max_angle>
            </horizontal>
          </scan>
          <range>
            <min>0.120000</min>
            <max>3.5</max>
            <resolution>0.015000</resolution>
          </range>
          <noise>
            <type>gaussian</type>
            <mean>0.0</mean>
            <stddev>0.01</stddev>
          </noise>
        </ray>
      </sensor>
    </link>

    <link name="left_wheel">

      <inertial>
        <pose>0 0.08 0.023 -1.57 0 0</pose>
        <inertia>
          <ixx>0.001</ixx>
          <ixy>0.000</ixy>
          <ixz>0.000</ixz>
          <iyy>0.001</iyy>
          <iyz>0.000</iyz>
          <izz>0.001</izz>
        </inertia>
        <mass>0.1</mass>
      </inertial>

      <collision name="left_wheel_collision">
        <pose>0 0.08 0.023 -1.57 0 0</pose>
        <geometry>
          <cylinder>
            <radius>0.033</radius>
            <length>0.018</length>
          </cylinder>
        </geometry>
          <surface>
            <friction>
              <ode>
                <mu>100000.0</mu>
                <mu2>100000.0</mu2>
                <fdir1>0 0 0</fdir1>
                <slip1>0.0</slip1>
                <slip2>0.0</slip2>
              </ode>
          </friction>
        </surface>
      </collision>

      <visual name="left_wheel_visual">
        <pose>0 0.08 0.023 0 0 0</pose>
        <geometry>
          <mesh>
            <uri>model://turtleBot/meshes/left_tire.stl</uri>
            <scale>0.001 0.001 0.001</scale>
          </mesh>
        </geometry>
      </visual>
    </link>

<link name='link_0'>
      <inertial>
        <mass>0.01</mass>
        <inertia>
          <ixx>0.166667</ixx>
          <ixy>0</ixy>
          <ixz>0</ixz>
          <iyy>0.166667</iyy>
          <iyz>0</iyz>
          <izz>0.166667</izz>
        </inertia>
      </inertial>
      <pose frame=''>-0.03533 0.002014 0.732871 1.5e-05 -0.007706 -5.2e-05</pose>
      <visual name='visual'>
        <pose frame=''>0 0 0 0 -0 0</pose>
        <geometry>
          <mesh>
            <uri>model://turtleBot/meshes/cubemesh.dae</uri>
            <scale>1 1 1</scale>
          </mesh>
        </geometry>
        <material>
          <script>
            <uri>model://turtleBot/materials/scripts</uri>
            <uri>model://turtleBot/materials/textures</uri>
            <name>cube</name>
          </script>
        </material>
        <transparency>0</transparency>
        <cast_shadows>1</cast_shadows>
      </visual>
      <collision name='collision'>
        <laser_retro>0</laser_retro>
        <max_contacts>10</max_contacts>
        <pose frame=''>0 0 0 0 -0 0</pose>
        <geometry>
          <mesh>
            <uri>model://turtleBot/meshes/cubemesh.dae</uri>
            <scale>1 1 1</scale>
          </mesh>
        </geometry>
        <surface>
          <friction>
            <ode>
              <mu>1</mu>
              <mu2>1</mu2>
              <fdir1>0 0 0</fdir1>
              <slip1>0</slip1>
              <slip2>0</slip2>
            </ode>
            <torsional>
              <coefficient>1</coefficient>
              <patch_radius>0</patch_radius>
              <surface_radius>0</surface_radius>
              <use_patch_radius>1</use_patch_radius>
              <ode>
                <slip>0</slip>
              </ode>
            </torsional>
          </friction>
          <bounce>
            <restitution_coefficient>0</restitution_coefficient>
            <threshold>1e+06</threshold>
          </bounce>
          <contact>
            <collide_without_contact>0</collide_without_contact>
            <collide_without_contact_bitmask>1</collide_without_contact_bitmask>
            <collide_bitmask>1</collide_bitmask>
            <ode>
              <soft_cfm>0</soft_cfm>
              <soft_erp>0.2</soft_erp>
              <kp>1e+13</kp>
              <kd>1</kd>
              <max_vel>0.01</max_vel>
              <min_depth>0</min_depth>
            </ode>
            <bullet>
              <split_impulse>1</split_impulse>
              <split_impulse_penetration_threshold>-0.01</split_impulse_penetration_threshold>
              <soft_cfm>0</soft_cfm>
              <soft_erp>0.2</soft_erp>
              <kp>1e+13</kp>
              <kd>1</kd>
            </bullet>
          </contact>
        </surface>
      </collision>
    </link>

    <link name="right_wheel">

      <inertial>
        <pose>0.0 -0.08 0.023 -1.57 0 0</pose>
        <inertia>
          <ixx>0.001</ixx>
          <ixy>0.000</ixy>
          <ixz>0.000</ixz>
          <iyy>0.001</iyy>
          <iyz>0.000</iyz>
          <izz>0.001</izz>
        </inertia>
        <mass>0.1</mass>
      </inertial>
    
      <collision name="right_wheel_collision">
        <pose>0.0 -0.08 0.023 -1.57 0 0</pose>
        <geometry>
          <cylinder>
            <radius>0.033</radius>
            <length>0.018</length>
          </cylinder>
        </geometry>
          <surface>
            <friction>
              <ode>
                <mu>100000.0</mu>
                <mu2>100000.0</mu2>
                <fdir1>0 0 0</fdir1>
                <slip1>0.0</slip1>
                <slip2>0.0</slip2>
              </ode>
          </friction>
        </surface>
      </collision>

      <visual name="right_wheel_visual">
        <pose>0.0 -0.08 0.023 0 0 0</pose>
        <geometry>
          <mesh>
            <uri>model://turtleBot/meshes/right_tire.stl</uri>
            <scale>0.001 0.001 0.001</scale>
          </mesh>
        </geometry>
      </visual>
    </link>

    <joint name="left_wheel_joint" type="revolute">
      <parent>base</parent>
      <child>left_wheel</child>
      <pose>0.0 0.08 0.023 -1.57 0 0</pose>
      <axis>
        <xyz>0 1 0</xyz>
        <use_parent_model_frame>1</use_parent_model_frame>
        <limit>
          <!-- <lower>-1e+16</lower>
          <upper>1e+16</upper>
          <effort>-1</effort>
          <velocity>-1</velocity> -->
        </limit>
        <dynamics>
          <spring_reference>0</spring_reference>
          <spring_stiffness>0</spring_stiffness>
          <damping>0</damping>
          <friction>0</friction>
        </dynamics>
      </axis>
    </joint>

    <joint name="right_wheel_joint" type="revolute">
      <parent>base</parent>
      <child>right_wheel</child>
      <pose>0.0 -0.08 0.023 -1.57 0 0</pose>
      <axis>
        <xyz>0 1 0</xyz>
        <use_parent_model_frame>1</use_parent_model_frame>
        <limit>
          <!-- <lower>-1e+16</lower>
          <upper>1e+16</upper>
          <effort>-1</effort>
          <velocity>-1</velocity> -->
        </limit>
        <dynamics>
          <spring_reference>0</spring_reference>
          <spring_stiffness>0</spring_stiffness>
          <damping>0</damping>
          <friction>0</friction>
        </dynamics>
      </axis>
    </joint>

    <joint name="lidar_joint" type="fixed">
      <parent>base</parent>
      <child>lidar</child>
      <pose>-0.032 0 0.171 0 0 0</pose>
      <axis>
        <xyz>0 0 1</xyz>
        <use_parent_model_frame>true</use_parent_model_frame>
      </axis>
    </joint>

    <joint name='base_JOINT_0' type='fixed'>
          <parent>base</parent>
          <child>link_0</child>
          <pose frame=''>0 0 0 0 -0 0</pose>
          <physics>
            <ode>
              <limit>
                <cfm>0</cfm>
                <erp>0.2</erp>
              </limit>
              <suspension>
                <cfm>0</cfm>
                <erp>0.2</erp>
              </suspension>
            </ode>
          </physics>
        </joint>

  <static>0</static>

    <plugin name='turtlebot3_burger_controller' filename='libgazebo_ros_diff_drive.so'>
      <commandTopic>turtleBot/cmd_vel</commandTopic>
      <odometryTopic>turtleBot/odom</odometryTopic>
      <odometryFrame>turtleBot/odom</odometryFrame>
      <odometrySource>world</odometrySource>
      <publishOdomTF>1</publishOdomTF>
      <robotBaseFrame>base</robotBaseFrame>
      <publishWheelTF>0</publishWheelTF>
      <publishTf>1</publishTf>
      <publishWheelJointState>1</publishWheelJointState>
      <legacyMode>0</legacyMode>
      <updateRate>30</updateRate>
      <leftJoint>left_wheel_joint</leftJoint>
      <rightJoint>right_wheel_joint</rightJoint>
      <wheelSeparation>0.160</wheelSeparation>
      <wheelDiameter>0.066</wheelDiameter>
      <wheelAcceleration>1</wheelAcceleration>
      <wheelTorque>10</wheelTorque>
      <rosDebugLevel>na</rosDebugLevel>
      <robotNamespace>/</robotNamespace>
    </plugin>
  
  </model>
</sdf>